Workbook

Sheet Cover
B2: Pandora A/S (PNDORA DC)
B3: Equity research model: DCF, trading comparables, scenarios, reverse DCF
B5: Author | C5: Lucile Engelaere, Master 1 CCA, IAE Lyon
B6: Model date | C6: 11 September 2026
B7: Units | C7: DKK million unless stated; per-share data in DKK
B8: Last reported period | C8: H1 2026 (interim report published 12 August 2026)
B10: Key outputs
B11: Recommendation | C11: =Summary!D22 -> BUY
B12: 12-month target price (DKK) | C12: =Summary!D17 -> 950
B13: Share price (DKK) | C13: =Inputs!C5 -> 827.4
B14: Upside to target | C14: =Summary!D18 -> 0.14817501
B15: Expected total return (incl. dividend) | C15: =Summary!D20 -> 0.17476432
B16: Active scenario | C16: =Inputs!C17 -> Base
B18: Colour code
B19: 1,234 | C19: Blue: hard-coded input, source in the cell comment
B20: 1,234 | C20: Black: formula
B21: 1,234 | C21: Green: link to another sheet
B22: 1,234 | C22: Yellow fill: key lever to test (scenario selector, WACC inputs, peer multiples)
B24: Structure
B25: Inputs | C25: Market data, scenario drivers (Bear / Base / Bull), operating and valuation assumptions
B26: Historicals | C26: FY2024A, FY2025A, H1 2025, H1 2026 and LTM, as reported; lease-adjusted FCFF
B27: Forecast | C27: P&L and lease-adjusted free cash flow, 2026E to 2031E (active scenario)
B28: WACC | C28: CAPM cost of equity, after-tax cost of debt, WACC
B29: DCF | C29: Discounted FCFF, terminal value, equity bridge, two sensitivity tables
B30: Scenarios | C30: Bear / Base / Bull DCFs in parallel, plus reverse DCF (market-implied margin)
B31: Comps | C31: Trading comparables, value implied on 2028E and discounted one year
B32: Summary | C32: Football field, blended target price, rating rule
B34: Main sources
C35: Pandora, Interim Report Q2 2026, Company Announcement 1015 (12 August 2026)
C36: Pandora, Interim Report Q4 2025, Company Announcement 997 (4 February 2026)
C37: Pandora, Interim Report Q1 2026, Company Announcement 1012 (6 May 2026)
C38: Market data: Investing.com (price, beta, broker targets, shareholders), Trading Economics (Bund yield)
C39: Peer multiples: GuruFocus, StockAnalysis, Seeking Alpha, ChartRow (indicative; refresh on Bloomberg)
B41: Academic exercise prepared for a master's application. Not investment advice.

Sheet Inputs
B1: Inputs and assumptions
B2: Hard-coded numbers in blue, sourced in cell comments
B4: Market data
B5: Share price (DKK) | C5: 827.4
B6: Shares outstanding (m) | C6: 74.8
B7: Market capitalisation (DKKm) | C7: =C5*C6 -> 61889.52
B8: Net debt excl. leases, 30/06/2026 (DKKm) | C8: =Historicals!F31 -> 9352
B9: Lease liabilities, 30/06/2026 (DKKm) | C9: =Historicals!F32 -> 6291
B10: NIBD incl. leases, 30/06/2026 (DKKm) | C10: =C8+C9 -> 15643
B11: Enterprise value incl. leases (DKKm) | C11: =C7+C10 -> 77532.52
B12: Next 12m dividend per share (DKK) | C12: 22
B13: 52-week low / high (DKK) | C13: 430 | D13: 904.4
B14: Broker targets: low / consensus / high (DKK) | C14: 730 | D14: 853.4 | E14: 900
B16: Scenario selector
B17: Active scenario | C17: =CHOOSE(C18,"Bear","Base","Bull") -> Base
B18: Selector: 1 = Bear, 2 = Base, 3 = Bull (change this cell) | C18: 2
B20: Scenario drivers | D20: 2026E | E20: 2027E | F20: 2028E | G20: 2029E | H20: 2030E | I20: 2031E
B21: Revenue growth in DKK (%)
B22: Bear | D22: 0.01 | E22: 0 | F22: 0.02 | G22: 0.025 | H22: 0.025 | I22: 0.025 | K22: Bear: platinum-plated range under-delivers, LFL stays negative in EMEA and North America
B23: Base | D23: 0.013 | E23: 0.04 | F23: 0.05 | G23: 0.05 | H23: 0.045 | I23: 0.04 | K23: Base: 2026 in line with the upgraded guidance (0-3% organic, FX c.-0.6%); LFL recovery from 2027
B24: Bull | D24: 0.018 | E24: 0.055 | F24: 0.065 | G24: 0.06 | H24: 0.055 | I24: 0.05 | K24: Bull: the design reset works, LFL back to 4-6% plus 2-3% from network expansion
B25: Active | D25: =CHOOSE($C$18,D22,D23,D24) -> 0.013 | E25: =CHOOSE($C$18,E22,E23,E24) -> 0.04 | F25: =CHOOSE($C$18,F22,F23,F24) -> 0.05 | G25: =CHOOSE($C$18,G22,G23,G24) -> 0.05 | H25: =CHOOSE($C$18,H22,H23,H24) -> 0.045 | I25: =CHOOSE($C$18,I22,I23,I24) -> 0.04
B27: EBIT margin, reported (%)
B28: Bear | D28: 0.22 | E28: 0.125 | F28: 0.16 | G28: 0.175 | H28: 0.18 | I28: 0.18 | K28: Bear: 2027 near the guidance floor; steady state 18% (silver stays high, plating needs price cuts)
B29: Base | D29: 0.225 | E29: 0.145 | F29: 0.195 | G29: 0.215 | H29: 0.225 | I29: 0.23 | K29: Base: 2027 trough, then recovery above the >21% ambition as the silver exposure falls
B30: Bull | D30: 0.23 | E30: 0.165 | F30: 0.215 | G30: 0.235 | H30: 0.245 | I30: 0.25 | K30: Bull: margin back to the pre-2025 level of c.25%
B31: Active | D31: =CHOOSE($C$18,D28,D29,D30) -> 0.225 | E31: =CHOOSE($C$18,E28,E29,E30) -> 0.145 | F31: =CHOOSE($C$18,F28,F29,F30) -> 0.195 | G31: =CHOOSE($C$18,G28,G29,G30) -> 0.215 | H31: =CHOOSE($C$18,H28,H29,H30) -> 0.225 | I31: =CHOOSE($C$18,I28,I29,I30) -> 0.23
B33: Common operating assumptions | D33: 2026E | E33: 2027E | F33: 2028E | G33: 2029E | H33: 2030E | I33: 2031E
B34: Right-of-use depreciation (% revenue) | D34: 0.046 | E34: 0.046 | F34: 0.046 | G34: 0.046 | H34: 0.046 | I34: 0.046
B35: Lease payments, principal + interest (% revenue) | D35: 0.053 | E35: 0.053 | F35: 0.053 | G35: 0.053 | H35: 0.053 | I35: 0.053
B36: Other D&A, PP&E and intangibles (% revenue) | D36: 0.035 | E36: 0.035 | F36: 0.035 | G36: 0.035 | H36: 0.035 | I36: 0.035
B37: Capex (% revenue) | D37: 0.07 | E37: 0.065 | F37: 0.06 | G37: 0.06 | H37: 0.058 | I37: 0.058
B38: NWC excl. derivatives, year-end (% revenue) | D38: 0.015 | E38: 0.02 | F38: 0.01 | G38: 0.005 | H38: 0.005 | I38: 0.005
B39: Effective tax rate (%) | D39: 0.25 | E39: 0.25 | F39: 0.25 | G39: 0.25 | H39: 0.25 | I39: 0.25
B40: Net financial expenses, IFRS 16 basis (DKKm) | D40: 1125 | E40: 1000 | F40: 950 | G40: 900 | H40: 900 | I40: 900
B42: Valuation assumptions
B43: Risk-free rate | C43: 0.033
B44: Equity risk premium | C44: 0.055
B45: Levered beta | C45: 1.2
B46: Pre-tax cost of debt | C46: 0.043
...

Sheet Historicals
B1: Historical financials, as reported
B2: Sources: Pandora interim reports Q4 2025 (4 Feb 2026) and Q2 2026 (12 Aug 2026). DKK million.
B4: Income statement | C4: FY2024A | D4: FY2025A | E4: H1 2025 | F4: H1 2026 | G4: LTM Jun-26
B5: Revenue | C5: 31680 | D5: 32549 | E5: 14421 | F5: 14328 | G5: =D5+F5-E5 -> 32456
B6: Organic growth (%) | C6: 0.13 | D6: 0.06 | E6: 0.07 | F6: 0.02
B7: Like-for-like growth (%) | C7: 0.07 | D7: 0.02 | E7: 0.04 | F7: 0
B8: Gross profit | C8: 25289 | D8: 25747 | E8: 11517 | F8: 11459 | G8: =D8+F8-E8 -> 25689
B9: Gross margin (%) | C9: =C8/C5 -> 0.79826389 | D9: =D8/D5 -> 0.79102277 | E9: =E8/E5 -> 0.798627 | F9: =F8/F5 -> 0.7997627 | G9: =G8/G5 -> 0.79150234
B10: EBITDA (IFRS 16) | C10: 10327 | D10: 10316 | E10: 4175 | F10: 4279 | G10: =D10+F10-E10 -> 10420
B11: EBITDA margin (%) | C11: =C10/C5 -> 0.32597854 | D11: =D10/D5 -> 0.31693754 | E11: =E10/E5 -> 0.28950836 | F11: =F10/F5 -> 0.29864601 | G11: =G10/G5 -> 0.32105004
B12: of which right-of-use depreciation | C12: 1343 | D12: 1466 | E12: 718 | F12: 768 | G12: =D12+F12-E12 -> 1516
B13: of which other D&A | C13: =C10-C14-C12 -> 1010 | D13: =D10-D14-D12 -> 1067 | E13: =E10-E14-E12 -> 529 | F13: =F10-F14-F12 -> 560 | G13: =G10-G14-G12 -> 1098
B14: EBIT | C14: 7974 | D14: 7783 | E14: 2928 | F14: 2951 | G14: =D14+F14-E14 -> 7806
B15: EBIT margin (%) | C15: =C14/C5 -> 0.25170455 | D15: =D14/D5 -> 0.23911641 | E15: =E14/E5 -> 0.20303724 | F15: =F14/F5 -> 0.20596036 | G15: =G14/G5 -> 0.24051023 | I15: FY2025 EBIT margin 23.9% vs 25.2% in FY2024: c.300bp of commodity, FX and tariff headwinds, partly offset.
B16: Net financials | C16: -1048 | D16: -870 | E16: -461 | F16: -515 | G16: =D16+F16-E16 -> -924 | I16: H1 2026 EBIT includes a DKK 180m one-off gain (partial refund of US IEEPA tariffs).
B17: Profit before tax | C17: =C14+C16 -> 6926 | D17: =D14+D16 -> 6913 | E17: =E14+E16 -> 2467 | F17: =F14+F16 -> 2436 | G17: =G14+G16 -> 6882
B18: Income tax | C18: -1699 | D18: -1671 | E18: -562 | F18: -619 | G18: =D18+F18-E18 -> -1728
B19: Net profit | C19: 5227 | D19: 5241 | E19: 1904 | F19: 1817 | G19: =D19+F19-E19 -> 5154
B20: EPS, basic (DKK) | C20: 64.8 | D20: 68.1 | E20: 24.4 | F20: 24.3 | G20: =D20+F20-E20 -> 68
B21: Dividend per share for the financial year (DKK) | C21: 20 | D21: 22
B22: Effective tax rate (%) | C22: =-C18/C17 -> 0.24530754 | D22: =-D18/D17 -> 0.2417185 | E22: =-E18/E17 -> 0.22780705 | F22: =-F18/F17 -> 0.25410509 | G22: =-G18/G17 -> 0.2510898
B24: Cash flow and balance sheet items | C24: FY2024A | D24: FY2025A | E24: H1 2025 | F24: H1 2026 | G24: LTM Jun-26
B25: Capex, total | C25: 1919 | D25: 1943 | E25: 1010 | F25: 899 | G25: =D25+F25-E25 -> 1832
B26: Lease repayments (principal) | C26: 1162 | D26: 1260 | E26: 636 | F26: 709 | G26: =D26+F26-E26 -> 1333
B27: Lease interest paid | C27: 381 | D27: 422 | E27: 206 | F27: 215 | G27: =D27+F27-E27 -> 431
B28: Free cash flow incl. lease payments (company definition) | C28: 6767 | D28: 5022 | E28: 173 | F28: 890 | G28: =D28+F28-E28 -> 5739
B29: NWC excl. derivatives, end of period | C29: -510 | D29: -352 | E29: 1112 | F29: 996 | G29: =F29 -> 996
B30: Capex (% revenue) | C30: =C25/C5 -> 0.060574495 | D30: =D25/D5 -> 0.059694614 | E30: =E25/E5 -> 0.070036752 | F30: =F25/F5 -> 0.062744277 | G30: =G25/G5 -> 0.056445649
B31: Net debt excl. leases | C31: =C33-C34 -> 5834 | D31: =D33-D34 -> 8051 | E31: =E33-E34 -> 9970 | F31: =F33-F34 -> 9352 | G31: =G33-G34 -> 9352
B32: Lease liabilities | C32: 5173 | D32: 5668 | E32: 5326 | F32: 6291 | G32: =F32 -> 6291
B33: Loans and borrowings excl. leases | C33: 8228 | D33: 9356 | E33: 10787 | F33: 10260 | G33: =F33 -> 10260
B34: Cash | C34: 2394 | D34: 1305 | E34: 817 | F34: 908 | G34: =F34 -> 908
B35: NIBD incl. leases (ties to reported NIBD) | C35: =C31+C32 -> 11007 | D35: =D31+D32 -> 13719 | E35: =E31+E32 -> 15296 | F35: =F31+F32 -> 15643 | G35: =G31+G32 -> 15643
B36: NIBD / EBITDA (x) | C36: =C35/C10 -> 1.0658468 | D36: =D35/D10 -> 1.3298759 | G36: =G35/G10 -> 1.5012476
B38: Unlevered free cash flow, model definition (lease-adjusted) | D38: FY2025A | F38: H1 2026
B39: EBIT | D39: =D14 -> 7783 | F39: =F14 -> 2951 | I39: Leases are treated as operating costs (EBIT + ROU depreciation - lease cash payments).
B40: + Right-of-use depreciation | D40: =D12 -> 1466 | F40: =F12 -> 768 | I40: Consistency: net debt in the equity bridge therefore EXCLUDES lease liabilities.
B41: - Lease payments (principal + interest) | D41: =-(D26+D27) -> -1682 | F41: =-(F26+F27) -> -924 | I41: FY2025A FCFF c.4.8bn vs company FCF incl. leases of 5.0bn (which does not deduct lease interest): consistent.
B42: EBIT after leases | D42: =SUM(D39:D41) -> 7567 | F42: =SUM(F39:F41) -> 2795 | I42: H1 2026 FCFF is deducted from FY2026E so that only H2 2026 is discounted from 30/06/2026.
B43: - Tax on EBIT after leases | D43: =-D42*Inputs!$D$39 -> -1891.75 | F43: =-F42*Inputs!$D$39 -> -698.75
...

Sheet Forecast
B1: Forecast: P&L and free cash flow (active scenario)
B2: DKK million. Drivers from Inputs; 2025A column from Historicals.
B4: Income statement | C4: 2025A | D4: 2026E | E4: 2027E | F4: 2028E | G4: 2029E | H4: 2030E | I4: 2031E
B5: Revenue | C5: =Historicals!D5 -> 32549 | D5: =C5*(1+Inputs!D25) -> 32972.137 | E5: =D5*(1+Inputs!E25) -> 34291.022 | F5: =E5*(1+Inputs!F25) -> 36005.574 | G5: =F5*(1+Inputs!G25) -> 37805.852 | H5: =G5*(1+Inputs!H25) -> 39507.116 | I5: =H5*(1+Inputs!I25) -> 41087.4
B6: growth (%) | C6: =Historicals!D5/Historicals!C5-1 -> 0.027430556 | D6: =D5/C5-1 -> 0.013 | E6: =E5/D5-1 -> 0.04 | F6: =F5/E5-1 -> 0.05 | G6: =G5/F5-1 -> 0.05 | H6: =H5/G5-1 -> 0.045 | I6: =I5/H5-1 -> 0.04
B7: EBIT margin (%) | C7: =Historicals!D15 -> 0.23911641 | D7: =Inputs!D31 -> 0.225 | E7: =Inputs!E31 -> 0.145 | F7: =Inputs!F31 -> 0.195 | G7: =Inputs!G31 -> 0.215 | H7: =Inputs!H31 -> 0.225 | I7: =Inputs!I31 -> 0.23
B8: EBIT | C8: =Historicals!D14 -> 7783 | D8: =D5*D7 -> 7418.7308 | E8: =E5*E7 -> 4972.1983 | F8: =F5*F7 -> 7021.0869 | G8: =G5*G7 -> 8128.2582 | H8: =H5*H7 -> 8889.101 | I8: =I5*I7 -> 9450.1021
B9: Right-of-use depreciation | C9: =Historicals!D12 -> 1466 | D9: =D5*Inputs!D34 -> 1516.7183 | E9: =E5*Inputs!E34 -> 1577.387 | F9: =F5*Inputs!F34 -> 1656.2564 | G9: =G5*Inputs!G34 -> 1739.0692 | H9: =H5*Inputs!H34 -> 1817.3273 | I9: =I5*Inputs!I34 -> 1890.0204
B10: Other D&A | C10: =Historicals!D13 -> 1067 | D10: =D5*Inputs!D36 -> 1154.0248 | E10: =E5*Inputs!E36 -> 1200.1858 | F10: =F5*Inputs!F36 -> 1260.1951 | G10: =G5*Inputs!G36 -> 1323.2048 | H10: =H5*Inputs!H36 -> 1382.749 | I10: =I5*Inputs!I36 -> 1438.059
B11: EBITDA (IFRS 16) | C11: =C8+C9+C10 -> 10316 | D11: =D8+D9+D10 -> 10089.474 | E11: =E8+E9+E10 -> 7749.7711 | F11: =F8+F9+F10 -> 9937.5383 | G11: =G8+G9+G10 -> 11190.532 | H11: =H8+H9+H10 -> 12089.177 | I11: =I8+I9+I10 -> 12778.181
B12: EBITDA margin (%) | C12: =C11/C5 -> 0.31693754 | D12: =D11/D5 -> 0.306 | E12: =E11/E5 -> 0.226 | F12: =F11/F5 -> 0.276 | G12: =G11/G5 -> 0.296 | H12: =H11/H5 -> 0.306 | I12: =I11/I5 -> 0.311
B13: Net financial expenses | C13: =Historicals!D16 -> -870 | D13: =-Inputs!D40 -> -1125 | E13: =-Inputs!E40 -> -1000 | F13: =-Inputs!F40 -> -950 | G13: =-Inputs!G40 -> -900 | H13: =-Inputs!H40 -> -900 | I13: =-Inputs!I40 -> -900
B14: Profit before tax | C14: =C8+C13 -> 6913 | D14: =D8+D13 -> 6293.7308 | E14: =E8+E13 -> 3972.1983 | F14: =F8+F13 -> 6071.0869 | G14: =G8+G13 -> 7228.2582 | H14: =H8+H13 -> 7989.101 | I14: =I8+I13 -> 8550.1021
B15: Income tax | C15: =Historicals!D18 -> -1671 | D15: =-D14*Inputs!D39 -> -1573.4327 | E15: =-E14*Inputs!E39 -> -993.04956 | F15: =-F14*Inputs!F39 -> -1517.7717 | G15: =-G14*Inputs!G39 -> -1807.0646 | H15: =-H14*Inputs!H39 -> -1997.2753 | I15: =-I14*Inputs!I39 -> -2137.5255
B16: Net profit | C16: =C14+C15 -> 5242 | D16: =D14+D15 -> 4720.2981 | E16: =E14+E15 -> 2979.1487 | F16: =F14+F15 -> 4553.3151 | G16: =G14+G15 -> 5421.1937 | H16: =H14+H15 -> 5991.8258 | I16: =I14+I15 -> 6412.5765
B17: Shares outstanding (m) | C17: =Inputs!C6 -> 74.8 | D17: =Inputs!$C$6 -> 74.8 | E17: =Inputs!$C$6 -> 74.8 | F17: =Inputs!$C$6 -> 74.8 | G17: =Inputs!$C$6 -> 74.8 | H17: =Inputs!$C$6 -> 74.8 | I17: =Inputs!$C$6 -> 74.8
B18: EPS (DKK) | C18: =Historicals!D20 -> 68.1 | D18: =D16/D17 -> 63.10559 | E18: =E16/E17 -> 39.828191 | F18: =F16/F17 -> 60.873197 | G18: =G16/G17 -> 72.475851 | H18: =H16/H17 -> 80.104623 | I18: =I16/I17 -> 85.729633
B19: EPS growth (%) | D19: =D18/C18-1 -> -0.073339356 | E19: =E18/D18-1 -> -0.36886429 | F19: =F18/E18-1 -> 0.52839472 | G19: =G18/F18-1 -> 0.19060366 | H19: =H18/G18-1 -> 0.10525949 | I19: =I18/H18-1 -> 0.070220797
B21: Lease-adjusted unlevered free cash flow | C21: 2025A | D21: 2026E | E21: 2027E | F21: 2028E | G21: 2029E | H21: 2030E | I21: 2031E
B22: EBIT | C22: =C8 -> 7783 | D22: =D8 -> 7418.7308 | E22: =E8 -> 4972.1983 | F22: =F8 -> 7021.0869 | G22: =G8 -> 8128.2582 | H22: =H8 -> 8889.101 | I22: =I8 -> 9450.1021
B23: + Right-of-use depreciation | C23: =C9 -> 1466 | D23: =D9 -> 1516.7183 | E23: =E9 -> 1577.387 | F23: =F9 -> 1656.2564 | G23: =G9 -> 1739.0692 | H23: =H9 -> 1817.3273 | I23: =I9 -> 1890.0204
B24: - Lease payments (principal + interest) | C24: =Historicals!D41 -> -1682 | D24: =-D5*Inputs!D35 -> -1747.5233 | E24: =-E5*Inputs!E35 -> -1817.4242 | F24: =-F5*Inputs!F35 -> -1908.2954 | G24: =-G5*Inputs!G35 -> -2003.7102 | H24: =-H5*Inputs!H35 -> -2093.8771 | I24: =-I5*Inputs!I35 -> -2177.6322
B25: EBIT after leases | C25: =C22+C23+C24 -> 7567 | D25: =D22+D23+D24 -> 7187.9259 | E25: =E22+E23+E24 -> 4732.1611 | F25: =F22+F23+F24 -> 6769.0478 | G25: =G22+G23+G24 -> 7863.6173 | H25: =H22+H23+H24 -> 8612.5512 | I25: =I22+I23+I24 -> 9162.4903
B26: - Tax on EBIT after leases | C26: =-C25*Inputs!D39 -> -1891.75 | D26: =-D25*Inputs!D39 -> -1796.9815 | E26: =-E25*Inputs!E39 -> -1183.0403 | F26: =-F25*Inputs!F39 -> -1692.262 | G26: =-G25*Inputs!G39 -> -1965.9043 | H26: =-H25*Inputs!H39 -> -2153.1378 | I26: =-I25*Inputs!I39 -> -2290.6226
B27: NOPAT | C27: =C25+C26 -> 5675.25 | D27: =D25+D26 -> 5390.9444 | E27: =E25+E26 -> 3549.1208 | F27: =F25+F26 -> 5076.7859 | G27: =G25+G26 -> 5897.713 | H27: =H25+H26 -> 6459.4134 | I27: =I25+I26 -> 6871.8677
B28: + Other D&A | C28: =C10 -> 1067 | D28: =D10 -> 1154.0248 | E28: =E10 -> 1200.1858 | F28: =F10 -> 1260.1951 | G28: =G10 -> 1323.2048 | H28: =H10 -> 1382.749 | I28: =I10 -> 1438.059
B29: - Capex | C29: =-Historicals!D25 -> -1943 | D29: =-D5*Inputs!D37 -> -2308.0496 | E29: =-E5*Inputs!E37 -> -2228.9165 | F29: =-F5*Inputs!F37 -> -2160.3344 | G29: =-G5*Inputs!G37 -> -2268.3511 | H29: =-H5*Inputs!H37 -> -2291.4127 | I29: =-I5*Inputs!I37 -> -2383.0692
B30: NWC excl. derivatives (year-end level) | C30: =Historicals!D29 -> -352 | D30: =D5*Inputs!D38 -> 494.58206 | E30: =E5*Inputs!E38 -> 685.82045 | F30: =F5*Inputs!F38 -> 360.05574 | G30: =G5*Inputs!G38 -> 189.02926 | H30: =H5*Inputs!H38 -> 197.53558 | I30: =I5*Inputs!I38 -> 205.437
B31: - Increase in NWC | C31: =-(Historicals!D29-Historicals!C29) -> -158 | D31: =-(D30-C30) -> -846.58205 | E31: =-(E30-D30) -> -191.23839 | F31: =-(F30-E30) -> 325.76471 | G31: =-(G30-F30) -> 171.02647 | H31: =-(H30-G30) -> -8.5063168 | I31: =-(I30-H30) -> -7.9014231
B32: Unlevered free cash flow (FCFF) | C32: =C27+C28+C29+C31 -> 4641.25 | D32: =D27+D28+D29+D31 -> 3390.3375 | E32: =E27+E28+E29+E31 -> 2329.1518 | F32: =F27+F28+F29+F31 -> 4502.4113 | G32: =G27+G28+G29+G31 -> 5123.5931 | H32: =H27+H28+H29+H31 -> 5542.2434 | I32: =I27+I28+I29+I31 -> 5918.9561
B33: FCFF / revenue (%) | C33: =C32/C5 -> 0.14259271 | D33: =D32/D5 -> 0.10282432 | E33: =E32/E5 -> 0.067923077 | F33: =F32/F5 -> 0.12504762 | G33: =G32/G5 -> 0.13552381 | H33: =H32/H5 -> 0.14028469 | I33: =I32/I5 -> 0.14405769
B35: Memo and multiples at the current share price | C35: 2025A | D35: 2026E | E35: 2027E | F35: 2028E | G35: 2029E | H35: 2030E | I35: 2031E
B36: EBITDA after leases (EBITDAaL) | C36: =C11+C24 -> 8634 | D36: =D11+D24 -> 8341.9507 | E36: =E11+E24 -> 5932.3469 | F36: =F11+F24 -> 8029.2429 | G36: =G11+G24 -> 9186.8221 | H36: =H11+H24 -> 9995.3003 | I36: =I11+I24 -> 10600.549
B37: P/E (x) | C37: =Inputs!$C$5/C18 -> 12.14978 | D37: =Inputs!$C$5/D18 -> 13.111358 | E37: =Inputs!$C$5/E18 -> 20.77423 | F37: =Inputs!$C$5/F18 -> 13.592189 | G37: =Inputs!$C$5/G18 -> 11.416216 | H37: =Inputs!$C$5/H18 -> 10.328992 | I37: =Inputs!$C$5/I18 -> 9.6512719
B38: EV incl. leases / EBITDA IFRS 16 (x) | C38: =Inputs!$C$11/C11 -> 7.5157542 | D38: =Inputs!$C$11/D11 -> 7.6844958 | E38: =Inputs!$C$11/E11 -> 10.004492 | F38: =Inputs!$C$11/F11 -> 7.8019845 | G38: =Inputs!$C$11/G11 -> 6.9284032 | H38: =Inputs!$C$11/H11 -> 6.4133826 | I38: =Inputs!$C$11/I11 -> 6.0675707
B39: FCFF yield on EV excl. leases (%) | C39: =C32/(Inputs!$C$7+Inputs!$C$8) -> 0.065148105 | D39: =D32/(Inputs!$C$7+Inputs!$C$8) -> 0.047589349 | E39: =E32/(Inputs!$C$7+Inputs!$C$8) -> 0.03269374 | F39: =F32/(Inputs!$C$7+Inputs!$C$8) -> 0.063199259 | G39: =G32/(Inputs!$C$7+Inputs!$C$8) -> 0.071918639 | H39: =H32/(Inputs!$C$7+Inputs!$C$8) -> 0.077795132 | I39: =I32/(Inputs!$C$7+Inputs!$C$8) -> 0.083082956
B40: Dividend yield at DKK 22 (%) | C40: =Inputs!$C$12/Inputs!$C$5 -> 0.026589316 | D40: =Inputs!$C$12/Inputs!$C$5 -> 0.026589316 | E40: =Inputs!$C$12/Inputs!$C$5 -> 0.026589316 | F40: =Inputs!$C$12/Inputs!$C$5 -> 0.026589316 | G40: =Inputs!$C$12/Inputs!$C$5 -> 0.026589316 | H40: =Inputs!$C$12/Inputs!$C$5 -> 0.026589316 | I40: =Inputs!$C$12/Inputs!$C$5 -> 0.026589316

Sheet WACC
B1: Weighted average cost of capital
B2: CAPM for equity. Lease liabilities excluded from debt, consistent with lease-adjusted FCFF.
B4: Risk-free rate | C4: =Inputs!C43 -> 0.033
B5: Levered beta | C5: =Inputs!C45 -> 1.2
B6: Equity risk premium | C6: =Inputs!C44 -> 0.055
B7: Cost of equity, Ke = Rf + beta x ERP | C7: =C4+C5*C6 -> 0.099 | E7: A beta above 1 reflects discretionary spending and commodity exposure.
B9: Pre-tax cost of debt | C9: =Inputs!C46 -> 0.043
B10: Tax rate | C10: =Inputs!C49 -> 0.25
B11: After-tax cost of debt | C11: =C9*(1-C10) -> 0.03225
B13: Weight of debt, D/(D+E) | C13: =Inputs!C47 -> 0.15
B14: Weight of equity, E/(D+E) | C14: =1-C13 -> 0.85
B16: WACC | C16: =C14*C7+C13*C11 -> 0.0889875 | E16: WACC close to 9% is prudent for a business with a c.40% ROIC; see the DCF sensitivity tables.
B18: Memo: current market D/(D+E), net debt excl. leases | C18: =Inputs!C8/(Inputs!C8+Inputs!C7) -> 0.13127176

Sheet DCF
B1: Discounted cash flow (active scenario)
B2: Valuation date 30/06/2026 (last balance sheet); mid-period discounting
B4: Free cash flow to the firm | D4: 2026E | E4: 2027E | F4: 2028E | G4: 2029E | H4: 2030E | I4: 2031E
B5: FCFF (Forecast) | D5: =Forecast!D32 -> 3390.3375 | E5: =Forecast!E32 -> 2329.1518 | F5: =Forecast!F32 -> 4502.4113 | G5: =Forecast!G32 -> 5123.5931 | H5: =Forecast!H32 -> 5542.2434 | I5: =Forecast!I32 -> 5918.9561
B6: Less: FCFF already generated in H1 2026 | D6: =-Historicals!F47 -> -409.25 | E6: 0 | F6: 0 | G6: 0 | H6: 0 | I6: 0
B7: FCFF to discount | D7: =D5+D6 -> 2981.0875 | E7: =E5+E6 -> 2329.1518 | F7: =F5+F6 -> 4502.4113 | G7: =G5+G6 -> 5123.5931 | H7: =H5+H6 -> 5542.2434 | I7: =I5+I6 -> 5918.9561
B8: Discount period, years from 30/06/2026 (mid-period) | D8: 0.25 | E8: =D8+0.75 -> 1 | F8: =E8+1 -> 2 | G8: =F8+1 -> 3 | H8: =G8+1 -> 4 | I8: =H8+1 -> 5
B9: Discount factor at WACC | D9: =1/(1+WACC!$C$16)^D8 -> 0.97891341 | E9: =1/(1+WACC!$C$16)^E8 -> 0.91828419 | F9: =1/(1+WACC!$C$16)^F8 -> 0.84324585 | G9: =1/(1+WACC!$C$16)^G8 -> 0.77433933 | H9: =1/(1+WACC!$C$16)^H8 -> 0.71106356 | I9: =1/(1+WACC!$C$16)^I8 -> 0.65295842
B10: Present value of FCFF | D10: =D7*D9 -> 2918.2266 | E10: =E7*E9 -> 2138.8232 | F10: =F7*F9 -> 3796.6396 | G10: =G7*G9 -> 3967.3996 | H10: =H7*H9 -> 3940.8873 | I10: =I7*I9 -> 3864.8322
B12: From enterprise value to value per share
B13: Sum of PV of FCFF (H2 2026 to 2031E) | D13: =SUM(D10:I10) -> 20626.809
B14: Terminal-year FCFF x (1 + g) | D14: =I5*(1+Inputs!C48) -> 6066.93
B15: Terminal value at end-2031 (Gordon growth) | D15: =D14/(WACC!C16-Inputs!C48) -> 94814.299
B16: Terminal value discount period (years) | D16: =I8+0.5 -> 5.5
B17: PV of terminal value | D17: =D15/(1+WACC!C16)^D16 -> 59326.389
B18: Enterprise value (excl. leases) | D18: =D13+D17 -> 79953.198
B19: Terminal value as % of EV | D19: =D17/D18 -> 0.74201396
B20: Less: net debt excl. leases (30/06/2026) | D20: =-Inputs!C8 -> -9352
B21: Equity value | D21: =D18+D20 -> 70601.198
B22: Shares outstanding (m) | D22: =Inputs!C6 -> 74.8
B23: DCF value per share (DKK) | D23: =D21/D22 -> 943.86628
B24: Upside vs current share price | D24: =D23/Inputs!C5-1 -> 0.14076176
B26: Sanity check: terminal value / 2031E EBITDA after leases (x) | D26: =D15/Forecast!I36 -> 8.9442817
B27: Sanity check: DCF value / 2028E EPS (x) | D27: =D23/Forecast!F18 -> 15.50545
B29: Sensitivity 1: value per share (DKK), WACC (rows) vs terminal growth (columns)
D30: =Inputs!$C$48+(-0.01) -> 0.015 | E30: =Inputs!$C$48+(-0.005) -> 0.02 | F30: =Inputs!$C$48+(0) -> 0.025 | G30: =Inputs!$C$48+(0.005) -> 0.03 | H30: =Inputs!$C$48+(0.01) -> 0.035
C31: =WACC!$C$16+(-0.01) -> 0.0789875 | D31: =(SUMPRODUCT($D$7:$I$7,1/(1+$C31)^$D$8:$I$8)+$I$5*(1+D$30)/($C31-D$30)/(1+$C31)^$D$16-Inputs!$C$8)/Inputs!$C$6 -> 984.21514 | E31: =(SUMPRODUCT($D$7:$I$7,1/(1+$C31)^$D$8:$I$8)+$I$5*(1+E$30)/($C31-E$30)/(1+$C31)^$D$16-Inputs!$C$8)/Inputs!$C$6 -> 1058.6685 | F31: =(SUMPRODUCT($D$7:$I$7,1/(1+$C31)^$D$8:$I$8)+$I$5*(1+F$30)/($C31-F$30)/(1+$C31)^$D$16-Inputs!$C$8)/Inputs!$C$6 -> 1146.9128 | G31: =(SUMPRODUCT($D$7:$I$7,1/(1+$C31)^$D$8:$I$8)+$I$5*(1+G$30)/($C31-G$30)/(1+$C31)^$D$16-Inputs!$C$8)/Inputs!$C$6 -> 1253.1707 | H31: =(SUMPRODUCT($D$7:$I$7,1/(1+$C31)^$D$8:$I$8)+$I$5*(1+H$30)/($C31-H$30)/(1+$C31)^$D$16-Inputs!$C$8)/Inputs!$C$6 -> 1383.5849
C32: =WACC!$C$16+(-0.005) -> 0.0839875 | D32: =(SUMPRODUCT($D$7:$I$7,1/(1+$C32)^$D$8:$I$8)+$I$5*(1+D$30)/($C32-D$30)/(1+$C32)^$D$16-Inputs!$C$8)/Inputs!$C$6 -> 901.44401 | E32: =(SUMPRODUCT($D$7:$I$7,1/(1+$C32)^$D$8:$I$8)+$I$5*(1+E$30)/($C32-E$30)/(1+$C32)^$D$16-Inputs!$C$8)/Inputs!$C$6 -> 963.79433 | F32: =(SUMPRODUCT($D$7:$I$7,1/(1+$C32)^$D$8:$I$8)+$I$5*(1+F$30)/($C32-F$30)/(1+$C32)^$D$16-Inputs!$C$8)/Inputs!$C$6 -> 1036.7148 | G32: =(SUMPRODUCT($D$7:$I$7,1/(1+$C32)^$D$8:$I$8)+$I$5*(1+G$30)/($C32-G$30)/(1+$C32)^$D$16-Inputs!$C$8)/Inputs!$C$6 -> 1123.1421 | H32: =(SUMPRODUCT($D$7:$I$7,1/(1+$C32)^$D$8:$I$8)+$I$5*(1+H$30)/($C32-H$30)/(1+$C32)^$D$16-Inputs!$C$8)/Inputs!$C$6 -> 1227.2121
C33: =WACC!$C$16+(0) -> 0.0889875 | D33: =(SUMPRODUCT($D$7:$I$7,1/(1+$C33)^$D$8:$I$8)+$I$5*(1+D$30)/($C33-D$30)/(1+$C33)^$D$16-Inputs!$C$8)/Inputs!$C$6 -> 829.97592 | E33: =(SUMPRODUCT($D$7:$I$7,1/(1+$C33)^$D$8:$I$8)+$I$5*(1+E$30)/($C33-E$30)/(1+$C33)^$D$16-Inputs!$C$8)/Inputs!$C$6 -> 882.79389 | F33: =(SUMPRODUCT($D$7:$I$7,1/(1+$C33)^$D$8:$I$8)+$I$5*(1+F$30)/($C33-F$30)/(1+$C33)^$D$16-Inputs!$C$8)/Inputs!$C$6 -> 943.86628 | G33: =(SUMPRODUCT($D$7:$I$7,1/(1+$C33)^$D$8:$I$8)+$I$5*(1+G$30)/($C33-G$30)/(1+$C33)^$D$16-Inputs!$C$8)/Inputs!$C$6 -> 1015.2921 | H33: =(SUMPRODUCT($D$7:$I$7,1/(1+$C33)^$D$8:$I$8)+$I$5*(1+H$30)/($C33-H$30)/(1+$C33)^$D$16-Inputs!$C$8)/Inputs!$C$6 -> 1099.948
C34: =WACC!$C$16+(0.005) -> 0.0939875 | D34: =(SUMPRODUCT($D$7:$I$7,1/(1+$C34)^$D$8:$I$8)+$I$5*(1+D$30)/($C34-D$30)/(1+$C34)^$D$16-Inputs!$C$8)/Inputs!$C$6 -> 767.66027 | E34: =(SUMPRODUCT($D$7:$I$7,1/(1+$C34)^$D$8:$I$8)+$I$5*(1+E$30)/($C34-E$30)/(1+$C34)^$D$16-Inputs!$C$8)/Inputs!$C$6 -> 812.85015 | F34: =(SUMPRODUCT($D$7:$I$7,1/(1+$C34)^$D$8:$I$8)+$I$5*(1+F$30)/($C34-F$30)/(1+$C34)^$D$16-Inputs!$C$8)/Inputs!$C$6 -> 864.59048 | G34: =(SUMPRODUCT($D$7:$I$7,1/(1+$C34)^$D$8:$I$8)+$I$5*(1+G$30)/($C34-G$30)/(1+$C34)^$D$16-Inputs!$C$8)/Inputs!$C$6 -> 924.41681 | H34: =(SUMPRODUCT($D$7:$I$7,1/(1+$C34)^$D$8:$I$8)+$I$5*(1+H$30)/($C34-H$30)/(1+$C34)^$D$16-Inputs!$C$8)/Inputs!$C$6 -> 994.38534
C35: =WACC!$C$16+(0.01) -> 0.0989875 | D35: =(SUMPRODUCT($D$7:$I$7,1/(1+$C35)^$D$8:$I$8)+$I$5*(1+D$30)/($C35-D$30)/(1+$C35)^$D$16-Inputs!$C$8)/Inputs!$C$6 -> 712.85878 | E35: =(SUMPRODUCT($D$7:$I$7,1/(1+$C35)^$D$8:$I$8)+$I$5*(1+E$30)/($C35-E$30)/(1+$C35)^$D$16-Inputs!$C$8)/Inputs!$C$6 -> 751.85954 | F35: =(SUMPRODUCT($D$7:$I$7,1/(1+$C35)^$D$8:$I$8)+$I$5*(1+F$30)/($C35-F$30)/(1+$C35)^$D$16-Inputs!$C$8)/Inputs!$C$6 -> 796.13157 | G35: =(SUMPRODUCT($D$7:$I$7,1/(1+$C35)^$D$8:$I$8)+$I$5*(1+G$30)/($C35-G$30)/(1+$C35)^$D$16-Inputs!$C$8)/Inputs!$C$6 -> 846.82099 | H35: =(SUMPRODUCT($D$7:$I$7,1/(1+$C35)^$D$8:$I$8)+$I$5*(1+H$30)/($C35-H$30)/(1+$C35)^$D$16-Inputs!$C$8)/Inputs!$C$6 -> 905.43219
B37: Sensitivity 2: value per share (DKK), WACC (rows) vs steady-state EBIT margin (columns)
D38: =Forecast!$I$7+(-0.03) -> 0.2 | E38: =Forecast!$I$7+(-0.015) -> 0.215 | F38: =Forecast!$I$7+(0) -> 0.23 | G38: =Forecast!$I$7+(0.015) -> 0.245 | H38: =Forecast!$I$7+(0.03) -> 0.26
C39: =WACC!$C$16+(-0.01) -> 0.0789875 | D39: =(SUMPRODUCT($D$7:$I$7,1/(1+$C39)^$D$8:$I$8)+(D$38-Forecast!$I$7)*Forecast!$I$5*(1-Inputs!$I$39)/(1+$C39)^$I$8+($I$5+(D$38-Forecast!$I$7)*Forecast!$I$5*(1-Inputs!$I$39))*(1+Inputs!$C$48)/($C39-Inputs!$C$48)/(1+$C39)^$D$16-Inputs!$C$8)/Inputs!$C$6 -> 983.99685 | E39: =(SUMPRODUCT($D$7:$I$7,1/(1+$C39)^$D$8:$I$8)+(E$38-Forecast!$I$7)*Forecast!$I$5*(1-Inputs!$I$39)/(1+$C39)^$I$8+($I$5+(E$38-Forecast!$I$7)*Forecast!$I$5*(1-Inputs!$I$39))*(1+Inputs!$C$48)/($C39-Inputs!$C$48)/(1+$C39)^$D$16-Inputs!$C$8)/Inputs!$C$6 -> 1065.4548 | F39: =(SUMPRODUCT($D$7:$I$7,1/(1+$C39)^$D$8:$I$8)+(F$38-Forecast!$I$7)*Forecast!$I$5*(1-Inputs!$I$39)/(1+$C39)^$I$8+($I$5+(F$38-Forecast!$I$7)*Forecast!$I$5*(1-Inputs!$I$39))*(1+Inputs!$C$48)/($C39-Inputs!$C$48)/(1+$C39)^$D$16-Inputs!$C$8)/Inputs!$C$6 -> 1146.9128 | G39: =(SUMPRODUCT($D$7:$I$7,1/(1+$C39)^$D$8:$I$8)+(G$38-Forecast!$I$7)*Forecast!$I$5*(1-Inputs!$I$39)/(1+$C39)^$I$8+($I$5+(G$38-Forecast!$I$7)*Forecast!$I$5*(1-Inputs!$I$39))*(1+Inputs!$C$48)/($C39-Inputs!$C$48)/(1+$C39)^$D$16-Inputs!$C$8)/Inputs!$C$6 -> 1228.3708 | H39: =(SUMPRODUCT($D$7:$I$7,1/(1+$C39)^$D$8:$I$8)+(H$38-Forecast!$I$7)*Forecast!$I$5*(1-Inputs!$I$39)/(1+$C39)^$I$8+($I$5+(H$38-Forecast!$I$7)*Forecast!$I$5*(1-Inputs!$I$39))*(1+Inputs!$C$48)/($C39-Inputs!$C$48)/(1+$C39)^$D$16-Inputs!$C$8)/Inputs!$C$6 -> 1309.8287
C40: =WACC!$C$16+(-0.005) -> 0.0839875 | D40: =(SUMPRODUCT($D$7:$I$7,1/(1+$C40)^$D$8:$I$8)+(D$38-Forecast!$I$7)*Forecast!$I$5*(1-Inputs!$I$39)/(1+$C40)^$I$8+($I$5+(D$38-Forecast!$I$7)*Forecast!$I$5*(1-Inputs!$I$39))*(1+Inputs!$C$48)/($C40-Inputs!$C$48)/(1+$C40)^$D$16-Inputs!$C$8)/Inputs!$C$6 -> 890.63443 | E40: =(SUMPRODUCT($D$7:$I$7,1/(1+$C40)^$D$8:$I$8)+(E$38-Forecast!$I$7)*Forecast!$I$5*(1-Inputs!$I$39)/(1+$C40)^$I$8+($I$5+(E$38-Forecast!$I$7)*Forecast!$I$5*(1-Inputs!$I$39))*(1+Inputs!$C$48)/($C40-Inputs!$C$48)/(1+$C40)^$D$16-Inputs!$C$8)/Inputs!$C$6 -> 963.67459 | F40: =(SUMPRODUCT($D$7:$I$7,1/(1+$C40)^$D$8:$I$8)+(F$38-Forecast!$I$7)*Forecast!$I$5*(1-Inputs!$I$39)/(1+$C40)^$I$8+($I$5+(F$38-Forecast!$I$7)*Forecast!$I$5*(1-Inputs!$I$39))*(1+Inputs!$C$48)/($C40-Inputs!$C$48)/(1+$C40)^$D$16-Inputs!$C$8)/Inputs!$C$6 -> 1036.7148 | G40: =(SUMPRODUCT($D$7:$I$7,1/(1+$C40)^$D$8:$I$8)+(G$38-Forecast!$I$7)*Forecast!$I$5*(1-Inputs!$I$39)/(1+$C40)^$I$8+($I$5+(G$38-Forecast!$I$7)*Forecast!$I$5*(1-Inputs!$I$39))*(1+Inputs!$C$48)/($C40-Inputs!$C$48)/(1+$C40)^$D$16-Inputs!$C$8)/Inputs!$C$6 -> 1109.7549 | H40: =(SUMPRODUCT($D$7:$I$7,1/(1+$C40)^$D$8:$I$8)+(H$38-Forecast!$I$7)*Forecast!$I$5*(1-Inputs!$I$39)/(1+$C40)^$I$8+($I$5+(H$38-Forecast!$I$7)*Forecast!$I$5*(1-Inputs!$I$39))*(1+Inputs!$C$48)/($C40-Inputs!$C$48)/(1+$C40)^$D$16-Inputs!$C$8)/Inputs!$C$6 -> 1182.7951
C41: =WACC!$C$16+(0) -> 0.0889875 | D41: =(SUMPRODUCT($D$7:$I$7,1/(1+$C41)^$D$8:$I$8)+(D$38-Forecast!$I$7)*Forecast!$I$5*(1-Inputs!$I$39)/(1+$C41)^$I$8+($I$5+(D$38-Forecast!$I$7)*Forecast!$I$5*(1-Inputs!$I$39))*(1+Inputs!$C$48)/($C41-Inputs!$C$48)/(1+$C41)^$D$16-Inputs!$C$8)/Inputs!$C$6 -> 811.91877 | E41: =(SUMPRODUCT($D$7:$I$7,1/(1+$C41)^$D$8:$I$8)+(E$38-Forecast!$I$7)*Forecast!$I$5*(1-Inputs!$I$39)/(1+$C41)^$I$8+($I$5+(E$38-Forecast!$I$7)*Forecast!$I$5*(1-Inputs!$I$39))*(1+Inputs!$C$48)/($C41-Inputs!$C$48)/(1+$C41)^$D$16-Inputs!$C$8)/Inputs!$C$6 -> 877.89253 | F41: =(SUMPRODUCT($D$7:$I$7,1/(1+$C41)^$D$8:$I$8)+(F$38-Forecast!$I$7)*Forecast!$I$5*(1-Inputs!$I$39)/(1+$C41)^$I$8+($I$5+(F$38-Forecast!$I$7)*Forecast!$I$5*(1-Inputs!$I$39))*(1+Inputs!$C$48)/($C41-Inputs!$C$48)/(1+$C41)^$D$16-Inputs!$C$8)/Inputs!$C$6 -> 943.86628 | G41: =(SUMPRODUCT($D$7:$I$7,1/(1+$C41)^$D$8:$I$8)+(G$38-Forecast!$I$7)*Forecast!$I$5*(1-Inputs!$I$39)/(1+$C41)^$I$8+($I$5+(G$38-Forecast!$I$7)*Forecast!$I$5*(1-Inputs!$I$39))*(1+Inputs!$C$48)/($C41-Inputs!$C$48)/(1+$C41)^$D$16-Inputs!$C$8)/Inputs!$C$6 -> 1009.84 | H41: =(SUMPRODUCT($D$7:$I$7,1/(1+$C41)^$D$8:$I$8)+(H$38-Forecast!$I$7)*Forecast!$I$5*(1-Inputs!$I$39)/(1+$C41)^$I$8+($I$5+(H$38-Forecast!$I$7)*Forecast!$I$5*(1-Inputs!$I$39))*(1+Inputs!$C$48)/($C41-Inputs!$C$48)/(1+$C41)^$D$16-Inputs!$C$8)/Inputs!$C$6 -> 1075.8138
C42: =WACC!$C$16+(0.005) -> 0.0939875 | D42: =(SUMPRODUCT($D$7:$I$7,1/(1+$C42)^$D$8:$I$8)+(D$38-Forecast!$I$7)*Forecast!$I$5*(1-Inputs!$I$39)/(1+$C42)^$I$8+($I$5+(D$38-Forecast!$I$7)*Forecast!$I$5*(1-Inputs!$I$39))*(1+Inputs!$C$48)/($C42-Inputs!$C$48)/(1+$C42)^$D$16-Inputs!$C$8)/Inputs!$C$6 -> 744.66268 | E42: =(SUMPRODUCT($D$7:$I$7,1/(1+$C42)^$D$8:$I$8)+(E$38-Forecast!$I$7)*Forecast!$I$5*(1-Inputs!$I$39)/(1+$C42)^$I$8+($I$5+(E$38-Forecast!$I$7)*Forecast!$I$5*(1-Inputs!$I$39))*(1+Inputs!$C$48)/($C42-Inputs!$C$48)/(1+$C42)^$D$16-Inputs!$C$8)/Inputs!$C$6 -> 804.62658 | F42: =(SUMPRODUCT($D$7:$I$7,1/(1+$C42)^$D$8:$I$8)+(F$38-Forecast!$I$7)*Forecast!$I$5*(1-Inputs!$I$39)/(1+$C42)^$I$8+($I$5+(F$38-Forecast!$I$7)*Forecast!$I$5*(1-Inputs!$I$39))*(1+Inputs!$C$48)/($C42-Inputs!$C$48)/(1+$C42)^$D$16-Inputs!$C$8)/Inputs!$C$6 -> 864.59048 | G42: =(SUMPRODUCT($D$7:$I$7,1/(1+$C42)^$D$8:$I$8)+(G$38-Forecast!$I$7)*Forecast!$I$5*(1-Inputs!$I$39)/(1+$C42)^$I$8+($I$5+(G$38-Forecast!$I$7)*Forecast!$I$5*(1-Inputs!$I$39))*(1+Inputs!$C$48)/($C42-Inputs!$C$48)/(1+$C42)^$D$16-Inputs!$C$8)/Inputs!$C$6 -> 924.55438 | H42: =(SUMPRODUCT($D$7:$I$7,1/(1+$C42)^$D$8:$I$8)+(H$38-Forecast!$I$7)*Forecast!$I$5*(1-Inputs!$I$39)/(1+$C42)^$I$8+($I$5+(H$38-Forecast!$I$7)*Forecast!$I$5*(1-Inputs!$I$39))*(1+Inputs!$C$48)/($C42-Inputs!$C$48)/(1+$C42)^$D$16-Inputs!$C$8)/Inputs!$C$6 -> 984.51827
C43: =WACC!$C$16+(0.01) -> 0.0989875 | D43: =(SUMPRODUCT($D$7:$I$7,1/(1+$C43)^$D$8:$I$8)+(D$38-Forecast!$I$7)*Forecast!$I$5*(1-Inputs!$I$39)/(1+$C43)^$I$8+($I$5+(D$38-Forecast!$I$7)*Forecast!$I$5*(1-Inputs!$I$39))*(1+Inputs!$C$48)/($C43-Inputs!$C$48)/(1+$C43)^$D$16-Inputs!$C$8)/Inputs!$C$6 -> 686.54066 | E43: =(SUMPRODUCT($D$7:$I$7,1/(1+$C43)^$D$8:$I$8)+(E$38-Forecast!$I$7)*Forecast!$I$5*(1-Inputs!$I$39)/(1+$C43)^$I$8+($I$5+(E$38-Forecast!$I$7)*Forecast!$I$5*(1-Inputs!$I$39))*(1+Inputs!$C$48)/($C43-Inputs!$C$48)/(1+$C43)^$D$16-Inputs!$C$8)/Inputs!$C$6 -> 741.33611 | F43: =(SUMPRODUCT($D$7:$I$7,1/(1+$C43)^$D$8:$I$8)+(F$38-Forecast!$I$7)*Forecast!$I$5*(1-Inputs!$I$39)/(1+$C43)^$I$8+($I$5+(F$38-Forecast!$I$7)*Forecast!$I$5*(1-Inputs!$I$39))*(1+Inputs!$C$48)/($C43-Inputs!$C$48)/(1+$C43)^$D$16-Inputs!$C$8)/Inputs!$C$6 -> 796.13157 | G43: =(SUMPRODUCT($D$7:$I$7,1/(1+$C43)^$D$8:$I$8)+(G$38-Forecast!$I$7)*Forecast!$I$5*(1-Inputs!$I$39)/(1+$C43)^$I$8+($I$5+(G$38-Forecast!$I$7)*Forecast!$I$5*(1-Inputs!$I$39))*(1+Inputs!$C$48)/($C43-Inputs!$C$48)/(1+$C43)^$D$16-Inputs!$C$8)/Inputs!$C$6 -> 850.92702 | H43: =(SUMPRODUCT($D$7:$I$7,1/(1+$C43)^$D$8:$I$8)+(H$38-Forecast!$I$7)*Forecast!$I$5*(1-Inputs!$I$39)/(1+$C43)^$I$8+($I$5+(H$38-Forecast!$I$7)*Forecast!$I$5*(1-Inputs!$I$39))*(1+Inputs!$C$48)/($C43-Inputs!$C$48)/(1+$C43)^$D$16-Inputs!$C$8)/Inputs!$C$6 -> 905.72247
B45: Sensitivity 2 changes the 2031E margin (and therefore the terminal value); 2026E-2030E are unchanged.

Sheet Scenarios
B1: Scenario DCFs in parallel, and reverse DCF
B2: Same mechanics as the DCF tab; only the growth and margin paths change
B4: Bear case | C4: 2025A | D4: 2026E | E4: 2027E | F4: 2028E | G4: 2029E | H4: 2030E | I4: 2031E
B5: Revenue growth | D5: =Inputs!D22 -> 0.01 | E5: =Inputs!E22 -> 0 | F5: =Inputs!F22 -> 0.02 | G5: =Inputs!G22 -> 0.025 | H5: =Inputs!H22 -> 0.025 | I5: =Inputs!I22 -> 0.025
B6: Revenue | C6: =Historicals!D5 -> 32549 | D6: =C6*(1+D5) -> 32874.49 | E6: =D6*(1+E5) -> 32874.49 | F6: =E6*(1+F5) -> 33531.98 | G6: =F6*(1+G5) -> 34370.279 | H6: =G6*(1+H5) -> 35229.536 | I6: =H6*(1+I5) -> 36110.275
B7: EBIT margin | D7: =Inputs!D28 -> 0.22 | E7: =Inputs!E28 -> 0.125 | F7: =Inputs!F28 -> 0.16 | G7: =Inputs!G28 -> 0.175 | H7: =Inputs!H28 -> 0.18 | I7: =Inputs!I28 -> 0.18
B8: EBIT | D8: =D6*D7 -> 7232.3878 | E8: =E6*E7 -> 4109.3112 | F8: =F6*F7 -> 5365.1168 | G8: =G6*G7 -> 6014.7989 | H8: =H6*H7 -> 6341.3165 | I8: =I6*I7 -> 6499.8494
B9: EBIT after leases | D9: =D8+D6*(Inputs!D34-Inputs!D35) -> 7002.2664 | E9: =E8+E6*(Inputs!E34-Inputs!E35) -> 3879.1898 | F9: =F8+F6*(Inputs!F34-Inputs!F35) -> 5130.3929 | G9: =G8+G6*(Inputs!G34-Inputs!G35) -> 5774.2069 | H9: =H8+H6*(Inputs!H34-Inputs!H35) -> 6094.7098 | I9: =I8+I6*(Inputs!I34-Inputs!I35) -> 6247.0775
B10: NOPAT | D10: =D9*(1-Inputs!D39) -> 5251.6998 | E10: =E9*(1-Inputs!E39) -> 2909.3924 | F10: =F9*(1-Inputs!F39) -> 3847.7947 | G10: =G9*(1-Inputs!G39) -> 4330.6552 | H10: =H9*(1-Inputs!H39) -> 4571.0323 | I10: =I9*(1-Inputs!I39) -> 4685.3081
B11: + Other D&A | D11: =D6*Inputs!D36 -> 1150.6072 | E11: =E6*Inputs!E36 -> 1150.6072 | F11: =F6*Inputs!F36 -> 1173.6193 | G11: =G6*Inputs!G36 -> 1202.9598 | H11: =H6*Inputs!H36 -> 1233.0338 | I11: =I6*Inputs!I36 -> 1263.8596
B12: - Capex | D12: =-D6*Inputs!D37 -> -2301.2143 | E12: =-E6*Inputs!E37 -> -2136.8418 | F12: =-F6*Inputs!F37 -> -2011.9188 | G12: =-G6*Inputs!G37 -> -2062.2168 | H12: =-H6*Inputs!H37 -> -2043.3131 | I12: =-I6*Inputs!I37 -> -2094.3959
B13: NWC level | C13: =Historicals!D29 -> -352 | D13: =D6*Inputs!D38 -> 493.11735 | E13: =E6*Inputs!E38 -> 657.4898 | F13: =F6*Inputs!F38 -> 335.3198 | G13: =G6*Inputs!G38 -> 171.8514 | H13: =H6*Inputs!H38 -> 176.14768 | I13: =I6*Inputs!I38 -> 180.55137
B14: - Increase in NWC | D14: =-(D13-C13) -> -845.11735 | E14: =-(E13-D13) -> -164.37245 | F14: =-(F13-E13) -> 322.17 | G14: =-(G13-F13) -> 163.4684 | H14: =-(H13-G13) -> -4.2962849 | I14: =-(I13-H13) -> -4.403692
B15: FCFF | D15: =D10+D11+D12+D14 -> 3255.9753 | E15: =E10+E11+E12+E14 -> 1758.7852 | F15: =F10+F11+F12+F14 -> 3331.6652 | G15: =G10+G11+G12+G14 -> 3634.8666 | H15: =H10+H11+H12+H14 -> 3756.4567 | I15: =I10+I11+I12+I14 -> 3850.3681
B16: FCFF to discount (H1 2026 deducted) | D16: =D15+DCF!D6 -> 2846.7253 | E16: =E15+DCF!E6 -> 1758.7852 | F16: =F15+DCF!F6 -> 3331.6652 | G16: =G15+DCF!G6 -> 3634.8666 | H16: =H15+DCF!H6 -> 3756.4567 | I16: =I15+DCF!I6 -> 3850.3681
B17: PV of FCFF | D17: =D16*DCF!D9 -> 2786.6975 | E17: =E16*DCF!E9 -> 1615.0646 | F17: =F16*DCF!F9 -> 2809.4128 | G17: =G16*DCF!G9 -> 2814.6202 | H17: =H16*DCF!H9 -> 2671.0795 | I17: =I16*DCF!I9 -> 2514.1303
B18: Enterprise value (sum of PV + PV of terminal value) | D18: =SUM(D17:I17)+I15*(1+Inputs!$C$48)/(WACC!$C$16-Inputs!$C$48)/(1+WACC!$C$16)^DCF!$D$16 -> 53803.695
B19: Equity value | D19: =D18-Inputs!$C$8 -> 44451.695
B20: Value per share (DKK) | D20: =D19/Inputs!$C$6 -> 594.274
B22: Base case | C22: 2025A | D22: 2026E | E22: 2027E | F22: 2028E | G22: 2029E | H22: 2030E | I22: 2031E
B23: Revenue growth | D23: =Inputs!D23 -> 0.013 | E23: =Inputs!E23 -> 0.04 | F23: =Inputs!F23 -> 0.05 | G23: =Inputs!G23 -> 0.05 | H23: =Inputs!H23 -> 0.045 | I23: =Inputs!I23 -> 0.04
B24: Revenue | C24: =Historicals!D5 -> 32549 | D24: =C24*(1+D23) -> 32972.137 | E24: =D24*(1+E23) -> 34291.022 | F24: =E24*(1+F23) -> 36005.574 | G24: =F24*(1+G23) -> 37805.852 | H24: =G24*(1+H23) -> 39507.116 | I24: =H24*(1+I23) -> 41087.4
B25: EBIT margin | D25: =Inputs!D29 -> 0.225 | E25: =Inputs!E29 -> 0.145 | F25: =Inputs!F29 -> 0.195 | G25: =Inputs!G29 -> 0.215 | H25: =Inputs!H29 -> 0.225 | I25: =Inputs!I29 -> 0.23
B26: EBIT | D26: =D24*D25 -> 7418.7308 | E26: =E24*E25 -> 4972.1983 | F26: =F24*F25 -> 7021.0869 | G26: =G24*G25 -> 8128.2582 | H26: =H24*H25 -> 8889.101 | I26: =I24*I25 -> 9450.1021
B27: EBIT after leases | D27: =D26+D24*(Inputs!D34-Inputs!D35) -> 7187.9259 | E27: =E26+E24*(Inputs!E34-Inputs!E35) -> 4732.1611 | F27: =F26+F24*(Inputs!F34-Inputs!F35) -> 6769.0478 | G27: =G26+G24*(Inputs!G34-Inputs!G35) -> 7863.6173 | H27: =H26+H24*(Inputs!H34-Inputs!H35) -> 8612.5512 | I27: =I26+I24*(Inputs!I34-Inputs!I35) -> 9162.4903
B28: NOPAT | D28: =D27*(1-Inputs!D39) -> 5390.9444 | E28: =E27*(1-Inputs!E39) -> 3549.1208 | F28: =F27*(1-Inputs!F39) -> 5076.7859 | G28: =G27*(1-Inputs!G39) -> 5897.713 | H28: =H27*(1-Inputs!H39) -> 6459.4134 | I28: =I27*(1-Inputs!I39) -> 6871.8677
B29: + Other D&A | D29: =D24*Inputs!D36 -> 1154.0248 | E29: =E24*Inputs!E36 -> 1200.1858 | F29: =F24*Inputs!F36 -> 1260.1951 | G29: =G24*Inputs!G36 -> 1323.2048 | H29: =H24*Inputs!H36 -> 1382.749 | I29: =I24*Inputs!I36 -> 1438.059
B30: - Capex | D30: =-D24*Inputs!D37 -> -2308.0496 | E30: =-E24*Inputs!E37 -> -2228.9165 | F30: =-F24*Inputs!F37 -> -2160.3344 | G30: =-G24*Inputs!G37 -> -2268.3511 | H30: =-H24*Inputs!H37 -> -2291.4127 | I30: =-I24*Inputs!I37 -> -2383.0692
B31: NWC level | C31: =Historicals!D29 -> -352 | D31: =D24*Inputs!D38 -> 494.58206 | E31: =E24*Inputs!E38 -> 685.82045 | F31: =F24*Inputs!F38 -> 360.05574 | G31: =G24*Inputs!G38 -> 189.02926 | H31: =H24*Inputs!H38 -> 197.53558 | I31: =I24*Inputs!I38 -> 205.437
B32: - Increase in NWC | D32: =-(D31-C31) -> -846.58205 | E32: =-(E31-D31) -> -191.23839 | F32: =-(F31-E31) -> 325.76471 | G32: =-(G31-F31) -> 171.02647 | H32: =-(H31-G31) -> -8.5063168 | I32: =-(I31-H31) -> -7.9014231
B33: FCFF | D33: =D28+D29+D30+D32 -> 3390.3375 | E33: =E28+E29+E30+E32 -> 2329.1518 | F33: =F28+F29+F30+F32 -> 4502.4113 | G33: =G28+G29+G30+G32 -> 5123.5931 | H33: =H28+H29+H30+H32 -> 5542.2434 | I33: =I28+I29+I30+I32 -> 5918.9561
B34: FCFF to discount (H1 2026 deducted) | D34: =D33+DCF!D6 -> 2981.0875 | E34: =E33+DCF!E6 -> 2329.1518 | F34: =F33+DCF!F6 -> 4502.4113 | G34: =G33+DCF!G6 -> 5123.5931 | H34: =H33+DCF!H6 -> 5542.2434 | I34: =I33+DCF!I6 -> 5918.9561
B35: PV of FCFF | D35: =D34*DCF!D9 -> 2918.2266 | E35: =E34*DCF!E9 -> 2138.8232 | F35: =F34*DCF!F9 -> 3796.6396 | G35: =G34*DCF!G9 -> 3967.3996 | H35: =H34*DCF!H9 -> 3940.8873 | I35: =I34*DCF!I9 -> 3864.8322
B36: Enterprise value (sum of PV + PV of terminal value) | D36: =SUM(D35:I35)+I33*(1+Inputs!$C$48)/(WACC!$C$16-Inputs!$C$48)/(1+WACC!$C$16)^DCF!$D$16 -> 79953.198
B37: Equity value | D37: =D36-Inputs!$C$8 -> 70601.198
B38: Value per share (DKK) | D38: =D37/Inputs!$C$6 -> 943.86628
B40: Bull case | C40: 2025A | D40: 2026E | E40: 2027E | F40: 2028E | G40: 2029E | H40: 2030E | I40: 2031E
B41: Revenue growth | D41: =Inputs!D24 -> 0.018 | E41: =Inputs!E24 -> 0.055 | F41: =Inputs!F24 -> 0.065 | G41: =Inputs!G24 -> 0.06 | H41: =Inputs!H24 -> 0.055 | I41: =Inputs!I24 -> 0.05
B42: Revenue | C42: =Historicals!D5 -> 32549 | D42: =C42*(1+D41) -> 33134.882 | E42: =D42*(1+E41) -> 34957.301 | F42: =E42*(1+F41) -> 37229.525 | G42: =F42*(1+G41) -> 39463.297 | H42: =G42*(1+H41) -> 41633.778 | I42: =H42*(1+I41) -> 43715.467
B43: EBIT margin | D43: =Inputs!D30 -> 0.23 | E43: =Inputs!E30 -> 0.165 | F43: =Inputs!F30 -> 0.215 | G43: =Inputs!G30 -> 0.235 | H43: =Inputs!H30 -> 0.245 | I43: =Inputs!I30 -> 0.25
...

Sheet Comps
B1: Trading comparables
B2: Multiples pulled on 14/09/2026 where a data feed covers the stock; otherwise flagged. Refresh on Bloomberg before submission.
B4: Peer group
B5: Company | C5: Ticker | D5: Positioning | E5: NTM P/E (x) | F5: EV/EBITDA (x) | G5: Beta
B6: Signet Jewelers | C6: SIG US | D6: US jewellery retail, mid-market | E6: 8 | F6: 6.9 | G6: 1.11 | H6: SOURCED. Alpha Vantage COMPANY_OVERVIEW 14/09/2026: forward P/E 8.02x, EV/EBITDA 6.91x, beta 1.111. Last quarter 31/07/2026.
B7: Tapestry | C7: TPR US | D7: Accessible luxury (Coach, Kate Spade) | E7: 14.9 | F7: 12.4 | G7: 1.43 | H7: SOURCED. Alpha Vantage 14/09/2026: forward P/E 14.93x, EV/EBITDA 12.39x, beta 1.432. FY to June 2026.
B8: Ralph Lauren | C8: RL US | D8: Accessible-to-premium lifestyle brand, global retail | E8: 18 | F8: 13.9 | G8: 1.35 | H8: SOURCED. Alpha Vantage 14/09/2026: forward P/E 18.02x, EV/EBITDA 13.86x, beta 1.353. FY to March.
B9: Chow Tai Fook | C9: 1929 HK | D9: Asian jewellery brand, vertically integrated | E9: 12.3 | F9: 7.5 | G9: n.a. | H9: NOT SOURCED. Hong Kong listing outside free feed coverage. StockAnalysis fwd P/E (Aug 2026), Seeking Alpha fwd EV/EBITDA c.7.4x (early 2026). VERIFY.
B10: Richemont | C10: CFR SW | D10: Hard-luxury reference (Cartier, Van Cleef) | E10: 24 | F10: 15 | G10: n.a. | H10: NOT SOURCED. Swiss listing outside free feed coverage. Own estimates from LTM EBITDA c.EUR 5.8bn and net cash c.EUR 8.5bn. VERIFY.
B13: Lower quartile | E13: =QUARTILE(E6:E10,1) -> 12.3 | F13: =QUARTILE(F6:F10,1) -> 7.5
B14: Median | E14: =MEDIAN(E6:E10) -> 14.9 | F14: =MEDIAN(F6:F10) -> 12.4 | G14: =MEDIAN(G6:G10) -> 1.35
B15: Upper quartile | E15: =QUARTILE(E6:E10,3) -> 18 | F15: =QUARTILE(F6:F10,3) -> 13.9
B16: Screened via Alpha Vantage and excluded: Brilliant Earth (negative EBITDA), Capri Holdings (fwd P/E 6.5x vs EV/EBITDA 14.2x, distorted by disposals) and Movado (wholesale watch distributor, 9% operating margin, USD 0.7bn cap: a different business model).
B17: Selection rule: brand-owned retail or jewellery category. Peer betas (median of the sourced names) support the 1.20 used for Pandora in the WACC tab.
B19: Pandora at the current share price
C20: 2026E | D20: 2027E | E20: 2028E
B21: P/E (x) | C21: =Forecast!D37 -> 13.111358 | D21: =Forecast!E37 -> 20.77423 | E21: =Forecast!F37 -> 13.592189
B22: EV incl. leases / EBITDA IFRS 16 (x) | C22: =Forecast!D38 -> 7.6844958 | D22: =Forecast!E38 -> 10.004492 | E22: =Forecast!F38 -> 7.8019845
B23: 2027E is the transition trough (platinum one-offs, silver cost at c.USD 65/oz), so 2027E multiples look inflated.
B25: Implied value per share: peer multiple x Pandora 2028E, discounted one year at the cost of equity
C26: Low (Q1) | D26: Median | E26: High (Q3)
B27: Pandora EPS 2028E (DKK) | C27: =Forecast!F18 -> 60.873197
B28: Pandora EBITDA after leases 2028E (DKKm) | C28: =Forecast!F36 -> 8029.2429
B29: Cost of equity | C29: =WACC!C7 -> 0.099
B31: P/E method (DKK per share) | C31: =$C$27*E13/(1+$C$29) -> 681.29238 | D31: =$C$27*E14/(1+$C$29) -> 825.3054 | E31: =$C$27*E15/(1+$C$29) -> 997.01324
B32: EV/EBITDA method (DKK per share) | C32: =($C$28*F13-Inputs!$C$8)/Inputs!$C$6/(1+$C$29) -> 618.78472 | D32: =($C$28*F14-Inputs!$C$8)/Inputs!$C$6/(1+$C$29) -> 1097.3833 | E32: =($C$28*F15-Inputs!$C$8)/Inputs!$C$6/(1+$C$29) -> 1243.893
B34: Why 2028E: first clean year after the silver-to-platinum transition.
B35: Lease basis: peers report under US GAAP where store rents sit above EBITDA, so their multiples are applied to Pandora EBITDA AFTER lease payments, with net debt EXCLUDING lease liabilities. Like-for-like on both sides.

Sheet Summary
B1: Valuation summary and recommendation
B2: Football field (DKK per share) and blended 12-month target price
B4: Football field
C5: Low | D5: Mid | E5: High | F5: High - Low
B6: DCF (Bear / active scenario / Bull) | C6: =Scenarios!D20 -> 594.274 | D6: =DCF!D23 -> 943.86628 | E6: =Scenarios!D56 -> 1125.0605 | F6: =E6-C6 -> 530.78651
B7: P/E comparables on 2028E | C7: =Comps!C31 -> 681.29238 | D7: =Comps!D31 -> 825.3054 | E7: =Comps!E31 -> 997.01324 | F7: =E7-C7 -> 315.72086
B8: EV/EBITDA comparables on 2028E | C8: =Comps!C32 -> 618.78472 | D8: =Comps!D32 -> 1097.3833 | E8: =Comps!E32 -> 1243.893 | F8: =E8-C8 -> 625.10832
B9: Broker targets (Aug-Sep 2026) | C9: =Inputs!C14 -> 730 | D9: =Inputs!D14 -> 853.4 | E9: =Inputs!E14 -> 900 | F9: =E9-C9 -> 170
B10: 52-week trading range | C10: =Inputs!C13 -> 430 | D10: =(Inputs!C13+Inputs!D13)/2 -> 667.2 | E10: =Inputs!D13 -> 904.4 | F10: =E10-C10 -> 474.4
B11: Current share price | D11: =Inputs!C5 -> 827.4
B13: Target price | C13: Weight | D13: Value
B14: DCF, active scenario | C14: =Inputs!C52 -> 0.7 | D14: =D6 -> 943.86628
B15: P/E comparables, median | C15: =Inputs!C53 -> 0.15 | D15: =D7 -> 825.3054
B16: EV/EBITDA comparables, median | C16: =Inputs!C54 -> 0.15 | D16: =D8 -> 1097.3833
B17: 12-month target price, rounded to DKK 10 | D17: =ROUND(SUMPRODUCT(C14:C16,D14:D16),-1) -> 950
B18: Upside to target | D18: =D17/Inputs!C5-1 -> 0.14817501
B19: Dividend yield, next 12 months | D19: =Inputs!C12/Inputs!C5 -> 0.026589316
B20: Expected total shareholder return | D20: =D18+D19 -> 0.17476432
B22: Recommendation | D22: =IF(D20>=Inputs!C56,"BUY",IF(D20<=Inputs!C57,"SELL","HOLD")) -> BUY
B24: Market-implied steady-state EBIT margin (reverse DCF) | D24: =Scenarios!D102 -> 0.20541394
B25: Base-case steady-state EBIT margin (2031E) | D25: =Inputs!I29 -> 0.23
B26: Management mid-term ambition | D26: >21%
